[2022-10-22 08:26:08,782] {logging_mixin.py:115} WARNING - /home/***/.local/lib/python3.7/site-packages/***/models/taskinstance.py:2445 SAWarning: TypeDecorator UtcDateTime(timezone=True) will not produce a cache key because the ``cache_ok`` attribute is not set to True.  This can have significant performance implications including some performance degradations in comparison to prior SQLAlchemy versions.  Set this attribute to True if this type object's state is safe to use in a cache key, or False to disable this warning. (Background on this error at: https://sqlalche.me/e/14/cprf)
[2022-10-22 08:26:08,797] {taskinstance.py:1159} INFO - Dependencies all met for <TaskInstance: target_ingest_dag.target_ingestion_task_2d scheduled__2022-10-22T07:05:00+00:00 [queued]>
[2022-10-22 08:26:08,823] {taskinstance.py:1159} INFO - Dependencies all met for <TaskInstance: target_ingest_dag.target_ingestion_task_2d scheduled__2022-10-22T07:05:00+00:00 [queued]>
[2022-10-22 08:26:08,825] {taskinstance.py:1356} INFO - 
--------------------------------------------------------------------------------
[2022-10-22 08:26:08,826] {taskinstance.py:1357} INFO - Starting attempt 2 of 2
[2022-10-22 08:26:08,827] {taskinstance.py:1358} INFO - 
--------------------------------------------------------------------------------
[2022-10-22 08:26:08,857] {taskinstance.py:1377} INFO - Executing <Task(PythonOperator): target_ingestion_task_2d> on 2022-10-22 07:05:00+00:00
[2022-10-22 08:26:08,866] {standard_task_runner.py:52} INFO - Started process 510 to run task
[2022-10-22 08:26:08,873] {standard_task_runner.py:79} INFO - Running: ['***', 'tasks', 'run', 'target_ingest_dag', 'target_ingestion_task_2d', 'scheduled__2022-10-22T07:05:00+00:00', '--job-id', '8', '--raw', '--subdir', 'DAGS_FOLDER/target_ingest_dag.py', '--cfg-path', '/tmp/tmp3u3q0mig', '--error-file', '/tmp/tmp6d9_j9m9']
[2022-10-22 08:26:08,876] {standard_task_runner.py:80} INFO - Job 8: Subtask target_ingestion_task_2d
[2022-10-22 08:26:09,028] {logging_mixin.py:115} WARNING - /home/***/.local/lib/python3.7/site-packages/***/models/dagrun.py:485 SAWarning: TypeDecorator UtcDateTime(timezone=True) will not produce a cache key because the ``cache_ok`` attribute is not set to True.  This can have significant performance implications including some performance degradations in comparison to prior SQLAlchemy versions.  Set this attribute to True if this type object's state is safe to use in a cache key, or False to disable this warning. (Background on this error at: https://sqlalche.me/e/14/cprf)
[2022-10-22 08:26:09,044] {task_command.py:369} INFO - Running <TaskInstance: target_ingest_dag.target_ingestion_task_2d scheduled__2022-10-22T07:05:00+00:00 [running]> on host b20dbd9b67c8
[2022-10-22 08:26:09,139] {logging_mixin.py:115} WARNING - /home/***/.local/lib/python3.7/site-packages/***/models/dagrun.py:485 SAWarning: TypeDecorator UtcDateTime(timezone=True) will not produce a cache key because the ``cache_ok`` attribute is not set to True.  This can have significant performance implications including some performance degradations in comparison to prior SQLAlchemy versions.  Set this attribute to True if this type object's state is safe to use in a cache key, or False to disable this warning. (Background on this error at: https://sqlalche.me/e/14/cprf)
[2022-10-22 08:26:09,282] {logging_mixin.py:115} WARNING - /home/***/.local/lib/python3.7/site-packages/***/models/renderedtifields.py:213 SAWarning: TypeDecorator UtcDateTime(timezone=True) will not produce a cache key because the ``cache_ok`` attribute is not set to True.  This can have significant performance implications including some performance degradations in comparison to prior SQLAlchemy versions.  Set this attribute to True if this type object's state is safe to use in a cache key, or False to disable this warning. (Background on this error at: https://sqlalche.me/e/14/cprf)
[2022-10-22 08:26:09,311] {taskinstance.py:1571} INFO - Exporting the following env vars:
AIRFLOW_CTX_DAG_EMAIL=rongshiu@gmail.com
AIRFLOW_CTX_DAG_OWNER=rongshiu@gmail.com
AIRFLOW_CTX_DAG_ID=target_ingest_dag
AIRFLOW_CTX_TASK_ID=target_ingestion_task_2d
AIRFLOW_CTX_EXECUTION_DATE=2022-10-22T07:05:00+00:00
AIRFLOW_CTX_TRY_NUMBER=2
AIRFLOW_CTX_DAG_RUN_ID=scheduled__2022-10-22T07:05:00+00:00
[2022-10-22 08:26:09,315] {target_ingest.py:10} INFO - Reading SQL file from path
[2022-10-22 08:26:09,317] {taskinstance.py:1889} ERROR - Task failed with exception
Traceback (most recent call last):
  File "/opt/airflow/dags/target_ingest.py", line 11, in target_ingest
    query = open(sql_path, 'r')
FileNotFoundError: [Errno 2] No such file or directory: '/sources/dags/2d.sql'

During handling of the above exception, another exception occurred:

Traceback (most recent call last):
  File "/home/airflow/.local/lib/python3.7/site-packages/airflow/operators/python.py", line 171, in execute
    return_value = self.execute_callable()
  File "/home/airflow/.local/lib/python3.7/site-packages/airflow/operators/python.py", line 189, in execute_callable
    return self.python_callable(*self.op_args, **self.op_kwargs)
  File "/opt/airflow/dags/target_ingest.py", line 28, in target_ingest
    logger.error('target_ingest pipeline failed due to {error}',error=e)
  File "/usr/local/lib/python3.7/logging/__init__.py", line 1407, in error
    self._log(ERROR, msg, args, **kwargs)
TypeError: _log() got an unexpected keyword argument 'error'
[2022-10-22 08:26:09,370] {taskinstance.py:1400} INFO - Marking task as FAILED. dag_id=target_ingest_dag, task_id=target_ingestion_task_2d, execution_date=20221022T070500, start_date=20221022T082608, end_date=20221022T082609
[2022-10-22 08:26:09,393] {logging_mixin.py:115} WARNING - /home/***/.local/lib/python3.7/site-packages/***/models/dagrun.py:485 SAWarning: TypeDecorator UtcDateTime(timezone=True) will not produce a cache key because the ``cache_ok`` attribute is not set to True.  This can have significant performance implications including some performance degradations in comparison to prior SQLAlchemy versions.  Set this attribute to True if this type object's state is safe to use in a cache key, or False to disable this warning. (Background on this error at: https://sqlalche.me/e/14/cprf)
[2022-10-22 08:26:09,425] {logging_mixin.py:115} WARNING - /home/***/.local/lib/python3.7/site-packages/***/utils/email.py:115 PendingDeprecationWarning: Fetching SMTP credentials from configuration variables will be deprecated in a future release. Please set credentials using a connection instead.
[2022-10-22 08:26:09,428] {configuration.py:494} WARNING - section/key [smtp/smtp_user] not found in config
[2022-10-22 08:26:09,429] {email.py:224} INFO - Email alerting: attempt 1
[2022-10-22 08:26:09,466] {configuration.py:494} WARNING - section/key [smtp/smtp_user] not found in config
[2022-10-22 08:26:09,467] {email.py:224} INFO - Email alerting: attempt 1
[2022-10-22 08:26:09,471] {taskinstance.py:1944} ERROR - Failed to send email to: ['rongshiu@gmail.com']
Traceback (most recent call last):
  File "/opt/airflow/dags/target_ingest.py", line 11, in target_ingest
    query = open(sql_path, 'r')
FileNotFoundError: [Errno 2] No such file or directory: '/sources/dags/2d.sql'

During handling of the above exception, another exception occurred:

Traceback (most recent call last):
  File "/home/airflow/.local/lib/python3.7/site-packages/airflow/models/taskinstance.py", line 1451, in _run_raw_task
    self._execute_task_with_callbacks(context, test_mode)
  File "/home/airflow/.local/lib/python3.7/site-packages/airflow/models/taskinstance.py", line 1598, in _execute_task_with_callbacks
    result = self._execute_task(context, task_orig)
  File "/home/airflow/.local/lib/python3.7/site-packages/airflow/models/taskinstance.py", line 1659, in _execute_task
    result = execute_callable(context=context)
  File "/home/airflow/.local/lib/python3.7/site-packages/airflow/operators/python.py", line 171, in execute
    return_value = self.execute_callable()
  File "/home/airflow/.local/lib/python3.7/site-packages/airflow/operators/python.py", line 189, in execute_callable
    return self.python_callable(*self.op_args, **self.op_kwargs)
  File "/opt/airflow/dags/target_ingest.py", line 28, in target_ingest
    logger.error('target_ingest pipeline failed due to {error}',error=e)
  File "/usr/local/lib/python3.7/logging/__init__.py", line 1407, in error
    self._log(ERROR, msg, args, **kwargs)
TypeError: _log() got an unexpected keyword argument 'error'

During handling of the above exception, another exception occurred:

Traceback (most recent call last):
  File "/home/airflow/.local/lib/python3.7/site-packages/airflow/models/taskinstance.py", line 2316, in email_alert
    send_email(task.email, subject, html_content)
  File "/home/airflow/.local/lib/python3.7/site-packages/airflow/utils/email.py", line 71, in send_email
    **kwargs,
  File "/home/airflow/.local/lib/python3.7/site-packages/airflow/utils/email.py", line 115, in send_email_smtp
    send_mime_email(e_from=mail_from, e_to=recipients, mime_msg=msg, conn_id=conn_id, dryrun=dryrun)
  File "/home/airflow/.local/lib/python3.7/site-packages/airflow/utils/email.py", line 226, in send_mime_email
    smtp_conn = _get_smtp_connection(smtp_host, smtp_port, smtp_timeout, smtp_ssl)
  File "/home/airflow/.local/lib/python3.7/site-packages/airflow/utils/email.py", line 260, in _get_smtp_connection
    else smtplib.SMTP(host=host, port=port, timeout=timeout)
  File "/usr/local/lib/python3.7/smtplib.py", line 251, in __init__
    (code, msg) = self.connect(host, port)
  File "/usr/local/lib/python3.7/smtplib.py", line 336, in connect
    self.sock = self._get_socket(host, port, self.timeout)
  File "/usr/local/lib/python3.7/smtplib.py", line 307, in _get_socket
    self.source_address)
  File "/usr/local/lib/python3.7/socket.py", line 728, in create_connection
    raise err
  File "/usr/local/lib/python3.7/socket.py", line 716, in create_connection
    sock.connect(sa)
OSError: [Errno 99] Cannot assign requested address

During handling of the above exception, another exception occurred:

Traceback (most recent call last):
  File "/home/airflow/.local/lib/python3.7/site-packages/airflow/models/taskinstance.py", line 1942, in handle_failure
    self.email_alert(error, task)
  File "/home/airflow/.local/lib/python3.7/site-packages/airflow/models/taskinstance.py", line 2318, in email_alert
    send_email(task.email, subject, html_content_err)
  File "/home/airflow/.local/lib/python3.7/site-packages/airflow/utils/email.py", line 71, in send_email
    **kwargs,
  File "/home/airflow/.local/lib/python3.7/site-packages/airflow/utils/email.py", line 115, in send_email_smtp
    send_mime_email(e_from=mail_from, e_to=recipients, mime_msg=msg, conn_id=conn_id, dryrun=dryrun)
  File "/home/airflow/.local/lib/python3.7/site-packages/airflow/utils/email.py", line 226, in send_mime_email
    smtp_conn = _get_smtp_connection(smtp_host, smtp_port, smtp_timeout, smtp_ssl)
  File "/home/airflow/.local/lib/python3.7/site-packages/airflow/utils/email.py", line 260, in _get_smtp_connection
    else smtplib.SMTP(host=host, port=port, timeout=timeout)
  File "/usr/local/lib/python3.7/smtplib.py", line 251, in __init__
    (code, msg) = self.connect(host, port)
  File "/usr/local/lib/python3.7/smtplib.py", line 336, in connect
    self.sock = self._get_socket(host, port, self.timeout)
  File "/usr/local/lib/python3.7/smtplib.py", line 307, in _get_socket
    self.source_address)
  File "/usr/local/lib/python3.7/socket.py", line 728, in create_connection
    raise err
  File "/usr/local/lib/python3.7/socket.py", line 716, in create_connection
    sock.connect(sa)
OSError: [Errno 99] Cannot assign requested address
[2022-10-22 08:26:09,523] {standard_task_runner.py:97} ERROR - Failed to execute job 8 for task target_ingestion_task_2d (_log() got an unexpected keyword argument 'error'; 510)
[2022-10-22 08:26:09,580] {local_task_job.py:156} INFO - Task exited with return code 1
[2022-10-22 08:26:09,696] {local_task_job.py:273} INFO - 0 downstream tasks scheduled from follow-on schedule check
