[2022-10-22 08:06:43,486] {taskinstance.py:1159} INFO - Dependencies all met for <TaskInstance: target_ingest_dag.target_ingestion_task_2a manual__2022-10-22T08:06:42.211846+00:00 [queued]>
[2022-10-22 08:06:43,518] {taskinstance.py:1159} INFO - Dependencies all met for <TaskInstance: target_ingest_dag.target_ingestion_task_2a manual__2022-10-22T08:06:42.211846+00:00 [queued]>
[2022-10-22 08:06:43,519] {taskinstance.py:1356} INFO - 
--------------------------------------------------------------------------------
[2022-10-22 08:06:43,522] {taskinstance.py:1357} INFO - Starting attempt 1 of 2
[2022-10-22 08:06:43,523] {taskinstance.py:1358} INFO - 
--------------------------------------------------------------------------------
[2022-10-22 08:06:43,557] {taskinstance.py:1377} INFO - Executing <Task(PythonOperator): target_ingestion_task_2a> on 2022-10-22 08:06:42.211846+00:00
[2022-10-22 08:06:43,572] {standard_task_runner.py:52} INFO - Started process 381 to run task
[2022-10-22 08:06:43,580] {standard_task_runner.py:79} INFO - Running: ['***', 'tasks', 'run', 'target_ingest_dag', 'target_ingestion_task_2a', 'manual__2022-10-22T08:06:42.211846+00:00', '--job-id', '4', '--raw', '--subdir', 'DAGS_FOLDER/target_ingest_dag.py', '--cfg-path', '/tmp/tmpgi410t9v', '--error-file', '/tmp/tmp7zhuci2r']
[2022-10-22 08:06:43,587] {standard_task_runner.py:80} INFO - Job 4: Subtask target_ingestion_task_2a
[2022-10-22 08:06:43,799] {task_command.py:369} INFO - Running <TaskInstance: target_ingest_dag.target_ingestion_task_2a manual__2022-10-22T08:06:42.211846+00:00 [running]> on host 66c339828860
[2022-10-22 08:06:44,142] {logging_mixin.py:115} WARNING - /home/***/.local/lib/python3.7/site-packages/***/models/renderedtifields.py:213 SAWarning: TypeDecorator UtcDateTime(timezone=True) will not produce a cache key because the ``cache_ok`` attribute is not set to True.  This can have significant performance implications including some performance degradations in comparison to prior SQLAlchemy versions.  Set this attribute to True if this type object's state is safe to use in a cache key, or False to disable this warning. (Background on this error at: https://sqlalche.me/e/14/cprf)
[2022-10-22 08:06:44,188] {taskinstance.py:1571} INFO - Exporting the following env vars:
AIRFLOW_CTX_DAG_EMAIL=rongshiu@gmail.com
AIRFLOW_CTX_DAG_OWNER=rongshiu@gmail.com
AIRFLOW_CTX_DAG_ID=target_ingest_dag
AIRFLOW_CTX_TASK_ID=target_ingestion_task_2a
AIRFLOW_CTX_EXECUTION_DATE=2022-10-22T08:06:42.211846+00:00
AIRFLOW_CTX_TRY_NUMBER=1
AIRFLOW_CTX_DAG_RUN_ID=manual__2022-10-22T08:06:42.211846+00:00
[2022-10-22 08:06:44,191] {target_ingest.py:10} INFO - Reading SQL file from path
[2022-10-22 08:06:44,193] {taskinstance.py:1889} ERROR - Task failed with exception
Traceback (most recent call last):
  File "/opt/airflow/dags/target_ingest.py", line 11, in target_ingest
    query = open(sql_path, 'r')
FileNotFoundError: [Errno 2] No such file or directory: '2a.sql'

During handling of the above exception, another exception occurred:

Traceback (most recent call last):
  File "/home/airflow/.local/lib/python3.7/site-packages/airflow/operators/python.py", line 171, in execute
    return_value = self.execute_callable()
  File "/home/airflow/.local/lib/python3.7/site-packages/airflow/operators/python.py", line 189, in execute_callable
    return self.python_callable(*self.op_args, **self.op_kwargs)
  File "/opt/airflow/dags/target_ingest.py", line 28, in target_ingest
    logger.error('target_ingest pipeline failed due to {error}',error=e)
  File "/usr/local/lib/python3.7/logging/__init__.py", line 1407, in error
    self._log(ERROR, msg, args, **kwargs)
TypeError: _log() got an unexpected keyword argument 'error'
[2022-10-22 08:06:44,254] {taskinstance.py:1400} INFO - Marking task as UP_FOR_RETRY. dag_id=target_ingest_dag, task_id=target_ingestion_task_2a, execution_date=20221022T080642, start_date=20221022T080643, end_date=20221022T080644
[2022-10-22 08:06:44,290] {standard_task_runner.py:97} ERROR - Failed to execute job 4 for task target_ingestion_task_2a (_log() got an unexpected keyword argument 'error'; 381)
[2022-10-22 08:06:44,372] {local_task_job.py:156} INFO - Task exited with return code 1
[2022-10-22 08:06:44,496] {local_task_job.py:273} INFO - 0 downstream tasks scheduled from follow-on schedule check
